Traceback (most recent call last):
  File "/usr/lib/python3.6/site-packages/requests/packages/urllib3/connectionpool.py", line 672, in urlopen
    chunked=chunked,
  File "/usr/lib/python3.6/site-packages/requests/packages/urllib3/connectionpool.py", line 387, in _make_request
    conn.request(method, url, **httplib_request_kw)
  File "/usr/lib64/python3.6/http/client.py", line 1254, in request
    self._send_request(method, url, body, headers, encode_chunked)
  File "/usr/lib64/python3.6/http/client.py", line 1300, in _send_request
    self.endheaders(body, encode_chunked=encode_chunked)
  File "/usr/lib64/python3.6/http/client.py", line 1249, in endheaders
    self._send_output(message_body, encode_chunked=encode_chunked)
  File "/usr/lib64/python3.6/http/client.py", line 1036, in _send_output
    self.send(msg)
  File "/usr/lib64/python3.6/http/client.py", line 974, in send
    self.connect()
  File "/usr/local/lib/python3.6/site-packages/docker/transport/unixconn.py", line 30, in connect
    sock.connect(self.unix_socket)
ConnectionRefusedError: [Errno 111] Connection refused

During handling of the above exception, another exception occurred:

Traceback (most recent call last):
  File "/usr/lib/python3.6/site-packages/requests/adapters.py", line 438, in send
    timeout=timeout
  File "/usr/lib/python3.6/site-packages/requests/packages/urllib3/connectionpool.py", line 720, in urlopen
    method, url, error=e, _pool=self, _stacktrace=sys.exc_info()[2]
  File "/usr/lib/python3.6/site-packages/requests/packages/urllib3/util/retry.py", line 400, in increment
    raise six.reraise(type(error), error, _stacktrace)
  File "/usr/local/lib/python3.6/site-packages/six.py", line 702, in reraise
    raise value.with_traceback(tb)
  File "/usr/lib/python3.6/site-packages/requests/packages/urllib3/connectionpool.py", line 672, in urlopen
    chunked=chunked,
  File "/usr/lib/python3.6/site-packages/requests/packages/urllib3/connectionpool.py", line 387, in _make_request
    conn.request(method, url, **httplib_request_kw)
  File "/usr/lib64/python3.6/http/client.py", line 1254, in request
    self._send_request(method, url, body, headers, encode_chunked)
  File "/usr/lib64/python3.6/http/client.py", line 1300, in _send_request
    self.endheaders(body, encode_chunked=encode_chunked)
  File "/usr/lib64/python3.6/http/client.py", line 1249, in endheaders
    self._send_output(message_body, encode_chunked=encode_chunked)
  File "/usr/lib64/python3.6/http/client.py", line 1036, in _send_output
    self.send(msg)
  File "/usr/lib64/python3.6/http/client.py", line 974, in send
    self.connect()
  File "/usr/local/lib/python3.6/site-packages/docker/transport/unixconn.py", line 30, in connect
    sock.connect(self.unix_socket)
requests.packages.urllib3.exceptions.ProtocolError: ('Connection aborted.', ConnectionRefusedError(111, 'Connection refused'))

During handling of the above exception, another exception occurred:

Traceback (most recent call last):
  File "/usr/local/lib/python3.6/site-packages/docker/api/client.py", line 214, in _retrieve_server_version
    return self.version(api_version=False)["ApiVersion"]
  File "/usr/local/lib/python3.6/site-packages/docker/api/daemon.py", line 181, in version
    return self._result(self._get(url), json=True)
  File "/usr/local/lib/python3.6/site-packages/docker/utils/decorators.py", line 46, in inner
    return f(self, *args, **kwargs)
  File "/usr/local/lib/python3.6/site-packages/docker/api/client.py", line 237, in _get
    return self.get(url, **self._set_request_timeout(kwargs))
  File "/usr/lib/python3.6/site-packages/requests/sessions.py", line 543, in get
    return self.request('GET', url, **kwargs)
  File "/usr/lib/python3.6/site-packages/requests/sessions.py", line 530, in request
    resp = self.send(prep, **send_kwargs)
  File "/usr/lib/python3.6/site-packages/requests/sessions.py", line 651, in send
    r = adapter.send(request, **kwargs)
  File "/usr/lib/python3.6/site-packages/requests/adapters.py", line 488, in send
    raise ConnectionError(err, request=request)
requests.exceptions.ConnectionError: ('Connection aborted.', ConnectionRefusedError(111, 'Connection refused'))

During handling of the above exception, another exception occurred:

Traceback (most recent call last):
  File "one-router-topo.py", line 64, in <module>
    d1 = net.addDocker(f'd1{cset}', dimage="ubuntu:trusty")
  File "../../../../mininet/net.py", line 1054, in addDocker
    return self.addHost(name, cls=cls, **params)
  File "../../../../mininet/net.py", line 239, in addHost
    h = cls( name, **defaults )
  File "../../../../mininet/node.py", line 784, in __init__
    self.d_client = docker.from_env()
  File "/usr/local/lib/python3.6/site-packages/docker/client.py", line 101, in from_env
    **kwargs_from_env(**kwargs)
  File "/usr/local/lib/python3.6/site-packages/docker/client.py", line 45, in __init__
    self.api = APIClient(*args, **kwargs)
  File "/usr/local/lib/python3.6/site-packages/docker/api/client.py", line 197, in __init__
    self._version = self._retrieve_server_version()
  File "/usr/local/lib/python3.6/site-packages/docker/api/client.py", line 222, in _retrieve_server_version
    f'Error while fetching server API version: {e}'
docker.errors.DockerException: Error while fetching server API version: ('Connection aborted.', ConnectionRefusedError(111, 'Connection refused'))
